Workbook
Name HWSheet: 1
Name \a: #N/A
Name \b: #N/A
Name _: "="
Name ____________a11: {"'장비'!$A$3:$M$12"}
Name ____________H3: {"'장비'!$A$3:$M$12"}
Name ______a11: {"'장비'!$A$3:$M$12"}
Name ______H3: {"'장비'!$A$3:$M$12"}
Name ____a11: {"'장비'!$A$3:$M$12"}
Name ____H3: {"'장비'!$A$3:$M$12"}
Name __a11: {"'장비'!$A$3:$M$12"}
Name __DemandLoad: TRUE
Name __H3: {"'장비'!$A$3:$M$12"}
Name __IntlFixup: TRUE
Name __tt1: "tt1"
Name _10A1_: {"Book1","civilbm.xls"}
Name _14A1_: {"Book1","civilbm.xls"}
Name _A1: {"Book1","civilbm.xls"}
Name _Regression_Int: 1
Name _tt1: "tt1"
Name √: "SQRT"
Name AAA: {"'장비'!$A$3:$M$12"}
Name aaafff: {"'장비'!$A$3:$M$12"}
Name ADITION: {"'장비'!$A$3:$M$12"}
Name ads: BlankMacro1
Name afsdf: {"Book1","civilbm.xls"}
Name agfg: {"'장비'!$A$3:$M$12"}
Name ANC: "Edit Box 57"
Name ASDD: {"Book1","attach.xls"}
Name basin: {"'장비'!$A$3:$M$12"}
Name Button_3: "vlvlist_vlvlist_List"
Name cbcv: {"Book1","civilbm.xls"}
Name civil2: {"'장비'!$A$3:$M$12"}
Name coping: BLCH
Name dddf: {"'장비'!$A$3:$M$12"}
Name Deck3: "Group 246"
Name dfdf: {"'장비'!$A$3:$M$12"}
Name dfdsfsdaf: BlankMacro1
Name dfgdf: {"Book1","civilbm.xls"}
Name DFGSDFGSDGSD: {"'장비'!$A$3:$M$12"}
Name DIAMOND: {"'장비'!$A$3:$M$12"}
Name ds: {"Book1","civilbm.xls"}
Name DSFS: {"Book1","attach.xls"}
Name ert: {"'장비'!$A$3:$M$12"}
Name erty: {"'장비'!$A$3:$M$12"}
Name ewrweq: {"'장비'!$A$3:$M$12"}
Name fda: BlankMacro1
Name fffffffg: {"'장비'!$A$3:$M$12"}
Name ffgfg: {"'장비'!$A$3:$M$12"}
Name fgfj: {"Book1","civilbm.xls"}
Name gd: BlankMacro1
Name gdd: {"Book1","civilbm.xls"}
Name ggg: BlankMacro1
Name gggg: {"'장비'!$A$3:$M$12"}
Name ggggg: {"'장비'!$A$3:$M$12"}
Name HTML: {"'장비'!$A$3:$M$12"}
Name HTML1: {"'장비'!$A$3:$M$12"}
Name kjkgh: {"'장비'!$A$3:$M$12"}
Name LCD: {"Book1","civilbm.xls"}
Name level: {"'장비'!$A$3:$M$12"}

Sheet 分项汇总表
B1: 拉迪亚码头投标报价表-二航院
B2: 序号 | C2: 名称 | D2: 二航院方案（PHC桩）
D3: 金额（美元）
B4: B | C4: 准备工作 | D4: ='清单 '!H96 -> 88722
B5: C | C5: 疏浚工程
B6: D | C6: 地基处理 | D6: ='清单 '!H177 -> 16476810
B7: E | C7: 码头 | D7: ='清单 '!H416-D8 -> 50033437
C8: 护岸 | D8: =SUM('清单 '!H353:H364) -> 23514886
B9: F | C9: 路面工程 | D9: ='清单 '!H1127 -> 29471443
B10: G | C10: 电气 | D10: ='清单 '!H1405 -> 14606322
B11: H | C11: 房建 | D11: ='清单 '!H1995 -> 1119479
B12: I | C12: Gate Complex | D12: ='清单 '!H2148 -> 1977668
C13: 直接费小计 | D13: =SUM(D4:D12) -> 137288767
C14: 关税 | D14: 11685730
C15: 项目总计 | D15: =SUM(D13:D14) -> 1.489745e+08

Sheet 清单 
B1: THE BILL OF QUANTITIES（拉迪亚码头-港湾-二航院）
B2: Item No. | C2: Description2 | D2: 清单说明 | E2: Unit2 | F2: Quantity
G3: 综合单价（美元） | H3: 合计（美元）
B5: CLASS A | C5: PRELIMANARIES | D5: PRELIMANARIES
B6: A.1 | C6: Fixed (non-time related) Items | D6: 固定（非计时）项目
B7: A.1.1 | C7: Site Establishment | D7: 场地建设 | E7: LS | F7: 1
B8: A.1.2 | C8: Site Disestablishment | D8: 场地拆除 | E8: LS | F8: 1
B9: A.1.3 | C9: Temporary Access Routes | D9: 临时道路 | E9: LS | F9: 1
B10: A.1.4 | C10: Safety & Emergency Response | D10: 安全与应急响应 | E10: LS | F10: 1
B11: A.1.5 | C11: Risk Assessment /Method Statements / HSSE Plan | D11: 风险评估/方法说明/健康安全环境计划 | E11: LS | F11: 1
B12: A.1.6 | C12: Quality Management/Assurance Plan | D12: 质量管理／保证计划 | E12: LS | F12: 1
B13: A.1.7 | C13: Contractor’s Environmental and Social Management Plan | D13: 承包商环境与社会管理计划 | E13: LS | F13: 1
B14: A.1.8 | C14: Engineers' Site Facilities | D14: 工程师现场设施设备 | E14: LS | F14: 1
B15: A.1.9 | C15: Project Security (establishment) | D15: 项目保安（设立） | E15: LS | F15: 1
B16: A.1.10 | C16: Mobilisation of Contractor's Plant and Equipment | D16: 承包商设备与机械进场
C17: Contractor to itemise major plant | D17: 承包商列明主要设备 | E17: LS | F17: 1
B18: A.1.10.1 | C18: Piling rigs | D18: 桩机 | E18: LS | F18: 1
B19: A.1.10.2 | C19: Cranes | D19: 起重机 | E19: LS | F19: 1
B20: A.1.10.3 | C20: Paving machines | D20: 铺路机械 | E20: LS | F20: 1
B21: A.1.10.X | C21: Other equipment - Contractor to specify | D21: 其他设备——由承包商指定 | E21: LS | F21: 1
B22: A.1.11 | C22: De-mobilisation of Contractor's Plant & Equipment | D22: 承包商设备与机械退场 | E22: LS | F22: 1
B23: A.1.12 | C23: Insurances | D23: 保险 | E23: LS | F23: 1
B24: A.1.13 | C24: Performance Security | D24: 履约保证金 | E24: LS | F24: 1
B25: A.1.14 | C25: Advance Payment Guarantee | D25: 预付款保函 | E25: LS | F25: 1
B26: A.1.15 | C26: Parent Company Guarantees | D26: 母公司担保 | E26: LS | F26: 1
B27: A.1.16 | C27: Site Signage | D27: 现场标识 | E27: LS | F27: 1
B28: A.1.17 | C28: Design | D28: 设计
B29: A.1.17.1 | C29: Earthworks Reclamation and Ground Improvement | D29: 土方回填与地基改良 | E29: LS | F29: 1
B30: A.1.17.2 | C30: Quay and other Suspended deck structures | D30: 码头及其他悬挂式甲板结构 | E30: LS | F30: 1
B31: A.1.17.3 | C31: Drainage | D31: 排水工程 | E31: LS | F31: 1
B32: A.1.17.4 | C32: Services and Utilities | D32: 管线及公用设施工程 | E32: LS | F32: 1
B33: A.1.17.5 | C33: Pavements | D33: 路面工程 | E33: LS | F33: 1
B34: A.1.17.6 | C34: Electrical works | D34: 电气工程 | E34: LS | F34: 1
B35: A.1.17.7 | C35: IT and Communications | D35: 信息技术与通信工程 | E35: LS | F35: 1
B36: A.1.17.8 | C36: Gate Complex | D36: 闸口综合体 | E36: LS | F36: 1
B37: A.1.17.9 | C37: Reefer Racks | D37: 冷藏货架 | E37: LS | F37: 1
B38: A.1.17.10 | C38: All other elements | D38: 所有其他要素 | E38: LS | F38: 1
B39: A.1.18 | C39: BIM 3D Modelling | D39: BIM 三维建模 | E39: LS | F39: 1
B40: A.1.19 | C40: Approvals and Permits | D40: 审批与许可证 | E40: LS | F40: 1
B41: A.1.20 | C41: Environmental Compliance Requirements | D41: 环境合规要求
...
